Workbook

Sheet Data Entry-V
B7: ° | C7: ’ | D7: " | E7: N/S or E/W
A8: Latitude | B8: 36 | C8: 50 | D8: 0 | E8: S | F8: =IF(E8="N",(B8+C8/60+D8/3600),(-1*(B8+C8/60+D8/3600))) -> -36.833333 | G8: =RADIANS(F8) -> -0.64286294
A9: Longitude | B9: 174 | C9: 28 | D9: 0 | E9: E | F9: =IF(E9="W",(B9+C9/60+D9/3600),(-1*(B9+C9/60+D9/3600))) -> -174.46667 | G9: =F9/15 -> -11.631111 | H9: (in hours)
A11: Band | B11: V
A12: Date | B12: 46033
A13: Count time | B13: 10 | D13: Gain | E13: 10
A15: Star | B15: R.A. | C15: Declination | E15: UT Date | F15: UT | G15: Count 1 | H15: Count 2 | I15: Count 3 | J15: Average count | K15: Star count | L15: Empirical SNR | M15: airmass | N15: v-V | O15: Dv
A16: KSI2 CMA | B16: =INDEX(Stars!$B$2:B275, MATCH(A16,Stars!$A$2:A275,)) -> 6.5843 | C16: =INDEX(Stars!$C$2:$C$275, MATCH(A16,Stars!$A$2:$A$275,)) -> -22.9648 | D16: Star deflection | E16: =B12 -> 46033 | F16: 0.43248843 | G16: 2551 | H16: 2553 | I16: 2555 | J16: =AVERAGE(G16:I16) -> 2553 | K16: =(J16-J17) -> 2024 | L16: =IF(AND(G16=H16,G16=I16),"1000",K16/_xlfn.STDEV.P(G16:I16)) -> 1239.4418 | M16: ='Airmass-V'!D2-(('Airmass-V'!D2-1)*(0.0018161+('Airmass-V'!D2-1)*(0.002875+('Airmass-V'!D2-1)*0.0008083))) -> 1.06808 | N16: =O16-INDEX(Stars!$D$1:$D$242, MATCH(A16,Stars!$A$1:$A$242,)) -> -12.805526 | O16: =-2.5*LOG10(K16) -> -8.2655263
D17: Sky deflection | E17: =E16 -> 46033 | F17: 0.43319444 | G17: 531 | H17: 527 | I17: 529 | J17: =AVERAGE(G17:I17) -> 529 | L17: =IF(AND(G17=H17,G17=I17),"1000",J17/_xlfn.STDEV.P(G17:I17)) -> 323.94502
A18: 60 ORI | B18: =INDEX(Stars!$B$2:B277, MATCH(A18,Stars!$A$2:A277,)) -> 5.9804 | C18: =INDEX(Stars!$C$2:$C$275, MATCH(A18,Stars!$A$2:$A$275,)) -> 0.553 | D18: Star deflection | E18: =E17 -> 46033 | F18: 0.43476852 | G18: 1561 | H18: 1570 | I18: 1566 | J18: =AVERAGE(G18:I18) -> 1565.6667 | K18: =(J18-J19) -> 1031.3333 | L18: =IF(AND(G18=H18,G18=I18),"1000",K18/_xlfn.STDEV.P(G18:I18)) -> 280.1176 | M18: ='Airmass-V'!D3-(('Airmass-V'!D3-1)*(0.0018161+('Airmass-V'!D3-1)*(0.002875+('Airmass-V'!D3-1)*0.0008083))) -> 1.2695997 | N18: =O18-INDEX(Stars!$D$1:$D$242, MATCH(A18,Stars!$A$1:$A$242,)) -> -12.743498 | O18: =-2.5*LOG10(K18) -> -7.5334976
D19: Sky deflection | E19: =E18 -> 46033 | F19: 0.43585648 | G19: 535 | H19: 535 | I19: 533 | J19: =AVERAGE(G19:I19) -> 534.33333 | L19: =IF(AND(G19=H19,G19=I19),"1000",J19/_xlfn.STDEV.P(G19:I19)) -> 566.74609
A20: HD 55111 | B20: =INDEX(Stars!$B$2:B279, MATCH(A20,Stars!$A$2:A279,)) -> 7.1976 | C20: =INDEX(Stars!$C$2:$C$275, MATCH(A20,Stars!$A$2:$A$275,)) -> 5.6547 | D20: Star deflection | E20: =E19 -> 46033 | F20: 0.43690972 | G20: 982 | H20: 981 | I20: 975 | J20: =AVERAGE(G20:I20) -> 979.33333 | K20: =(J20-J21) -> 440 | L20: =IF(AND(G20=H20,G20=I20),"1000",K20/_xlfn.STDEV.P(G20:I20)) -> 142.33926 | M20: ='Airmass-V'!D4-(('Airmass-V'!D4-1)*(0.0018161+('Airmass-V'!D4-1)*(0.002875+('Airmass-V'!D4-1)*0.0008083))) -> 1.5104501 | N20: =O20-INDEX(Stars!$D$1:$D$242, MATCH(A20,Stars!$A$1:$A$242,)) -> -12.688632 | O20: =-2.5*LOG10(K20) -> -6.6086317
D21: Sky deflection | E21: =E20 -> 46033 | F21: 0.4375 | G21: 537 | H21: 544 | I21: 537 | J21: =AVERAGE(G21:I21) -> 539.33333 | L21: =IF(AND(G21=H21,G21=I21),"1000",J21/_xlfn.STDEV.P(G21:I21)) -> 163.44268
A22: HD 65900 | B22: =INDEX(Stars!$B$2:B281, MATCH(A22,Stars!$A$2:A281,)) -> 8.0205 | C22: =INDEX(Stars!$C$2:$C$275, MATCH(A22,Stars!$A$2:$A$275,)) -> 4.8667 | D22: Star deflection | E22: =E21 -> 46033 | F22: 0.43876157 | G22: 1161 | H22: 1169 | I22: 1171 | J22: =AVERAGE(G22:I22) -> 1167 | K22: =(J22-J23) -> 625.66667 | L22: =IF(AND(G22=H22,G22=I22),"1000",K22/_xlfn.STDEV.P(G22:I22)) -> 144.81369 | M22: ='Airmass-V'!D5-(('Airmass-V'!D5-1)*(0.0018161+('Airmass-V'!D5-1)*(0.002875+('Airmass-V'!D5-1)*0.0008083))) -> 1.7017228 | N22: =O22-INDEX(Stars!$D$1:$D$242, MATCH(A22,Stars!$A$1:$A$242,)) -> -12.630858 | O22: =-2.5*LOG10(K22) -> -6.9908575
D23: Sky deflection | E23: =E22 -> 46033 | F23: 0.43930556 | G23: 541 | H23: 543 | I23: 540 | J23: =AVERAGE(G23:I23) -> 541.33333 | L23: =IF(AND(G23=H23,G23=I23),"1000",J23/_xlfn.STDEV.P(G23:I23)) -> 434.03226
A24: HD 76757 | B24: =INDEX(Stars!$B$2:B283, MATCH(A24,Stars!$A$2:A283,)) -> 8.9689 | C24: =INDEX(Stars!$C$2:$C$275, MATCH(A24,Stars!$A$2:$A$275,)) -> 1.5416 | D24: Star deflection | E24: =E23 -> 46033 | F24: 0.44055556 | G24: 789 | H24: 791 | I24: 793 | J24: =AVERAGE(G24:I24) -> 791 | K24: =(J24-J25) -> 243.33333 | L24: =IF(AND(G24=H24,G24=I24),"1000",K24/_xlfn.STDEV.P(G24:I24)) -> 149.01063 | M24: ='Airmass-V'!D6-(('Airmass-V'!D6-1)*(0.0018161+('Airmass-V'!D6-1)*(0.002875+('Airmass-V'!D6-1)*0.0008083))) -> 2.0239617 | N24: =O24-INDEX(Stars!$D$1:$D$242, MATCH(A24,Stars!$A$1:$A$242,)) -> -12.555504 | O24: =-2.5*LOG10(K24) -> -5.965504
D25: Sky deflection | E25: =E24 -> 46033 | F25: 0.44114583 | G25: 549 | H25: 548 | I25: 546 | J25: =AVERAGE(G25:I25) -> 547.66667 | L25: =IF(AND(G25=H25,G25=I25),"1000",J25/_xlfn.STDEV.P(G25:I25)) -> 439.11022
M27: kapV= | N27: =(5*(M16*N16+M18*N18+M20*N20+M22*N22+M24*N24)-SUM(M16:M24)*SUM(N16:N24))/(5*(M16^2+M18^2+M20^2+M22^2+M24^2)-((SUM(M16:M24)^2))) -> 0.26044288
M28: R^2= | N28: =((5*(M16*N16+M18*N18+M20*N20+M22*N22+M24*N24)-SUM(M16:M24)*SUM(N16:N24))/((SQRT((5*(M16^2+M18^2+M20^2+M22^2+M24^2)-(SUM(M16:M24)^2))))*(SQRT((5*(N16^2+N18^2+N20^2+N22^2+N24^2)-((SUM(N16:N24)^2)))))))^2 -> 0.99756343

Sheet Data Entry-B
A11: Band | B11: B
A12: Date | B12: ='Data Entry-V'!B12 -> 46033
A13: Count time | B13: 10 | D13: Gain | E13: ='Data Entry-V'!E13 -> 10
A15: Star | B15: R.A. | C15: Declination | E15: UT Date | F15: UT | G15: Count 1 | H15: Count 2 | I15: Count 3 | J15: Average count | K15: Star count | L15: Empirical SNR | M15: airmass | N15: b-B | O15: ∆b
A16: ='Data Entry-V'!A16 -> KSI2 CMA | B16: ='Data Entry-V'!B16 -> 6.5843 | C16: ='Data Entry-V'!C16 -> -22.9648 | D16: Star deflection | E16: =B12 -> 46033 | J16: =AVERAGE(G16:I16) -> #DIV/0! | K16: =(J16-J17) -> #DIV/0! | L16: =IF(AND(G16=H16,G16=I16),"1000",K16/_xlfn.STDEV.P(G16:I16)) -> 1000 | M16: ='Airmass-B'!D2-(('Airmass-B'!D2-1)*(0.0018161+('Airmass-B'!D2-1)*(0.002875+('Airmass-B'!D2-1)*0.0008083))) -> -2.0037608 | N16: =O16-(INDEX(Stars!$D$1:$D$242, MATCH(A16,Stars!$A$1:$A$242,))+INDEX(Stars!$E$1:$E$242, MATCH(A16,Stars!$A$1:$A$242,))) -> #DIV/0! | O16: =-2.5*LOG10(K16) -> #DIV/0!
D17: Sky deflection | E17: =E16 -> 46033 | J17: =AVERAGE(G17:I17) -> #DIV/0! | L17: =IF(AND(G17=H17,G17=I17),"1000",J17/_xlfn.STDEV.P(G17:I17)) -> 1000
A18: ='Data Entry-V'!A18 -> 60 ORI | B18: ='Data Entry-V'!B18 -> 5.9804 | C18: ='Data Entry-V'!C18 -> 0.553 | D18: Star deflection | E18: =E17 -> 46033 | J18: =AVERAGE(G18:I18) -> #DIV/0! | K18: =(J18-J19) -> #DIV/0! | L18: =IF(AND(G18=H18,G18=I18),"1000",K18/_xlfn.STDEV.P(G18:I18)) -> 1000 | M18: ='Airmass-B'!D3-(('Airmass-B'!D3-1)*(0.0018161+('Airmass-B'!D3-1)*(0.002875+('Airmass-B'!D3-1)*0.0008083))) -> -1.2868402 | N18: =O18-(INDEX(Stars!$D$1:$D$242, MATCH(A18,Stars!$A$1:$A$242,))+INDEX(Stars!$E$1:$E$242, MATCH(A18,Stars!$A$1:$A$242,))) -> #DIV/0! | O18: =-2.5*LOG10(K18) -> #DIV/0!
D19: Sky deflection | E19: =E18 -> 46033 | J19: =AVERAGE(G19:I19) -> #DIV/0! | L19: =IF(AND(G19=H19,G19=I19),"1000",J19/_xlfn.STDEV.P(G19:I19)) -> 1000
A20: ='Data Entry-V'!A20 -> HD 55111 | B20: ='Data Entry-V'!B20 -> 7.1976 | C20: ='Data Entry-V'!C20 -> 5.6547 | D20: Star deflection | E20: =E19 -> 46033 | J20: =AVERAGE(G20:I20) -> #DIV/0! | K20: =(J20-J21) -> #DIV/0! | L20: =IF(AND(G20=H20,G20=I20),"1000",K20/_xlfn.STDEV.P(G20:I20)) -> 1000 | M20: ='Airmass-B'!D4-(('Airmass-B'!D4-1)*(0.0018161+('Airmass-B'!D4-1)*(0.002875+('Airmass-B'!D4-1)*0.0008083))) -> -1.1716358 | N20: =O20-(INDEX(Stars!$D$1:$D$242, MATCH(A20,Stars!$A$1:$A$242,))+INDEX(Stars!$E$1:$E$242, MATCH(A20,Stars!$A$1:$A$242,))) -> #DIV/0! | O20: =-2.5*LOG10(K20) -> #DIV/0!
D21: Sky deflection | E21: =E20 -> 46033 | J21: =AVERAGE(G21:I21) -> #DIV/0! | L21: =IF(AND(G21=H21,G21=I21),"1000",J21/_xlfn.STDEV.P(G21:I21)) -> 1000
A22: ='Data Entry-V'!A22 -> HD 65900 | B22: ='Data Entry-V'!B22 -> 8.0205 | C22: ='Data Entry-V'!C22 -> 4.8667 | D22: Star deflection | E22: =E21 -> 46033 | J22: =AVERAGE(G22:I22) -> #DIV/0! | K22: =(J22-J23) -> #DIV/0! | L22: =IF(AND(G22=H22,G22=I22),"1000",K22/_xlfn.STDEV.P(G22:I22)) -> 1000 | M22: ='Airmass-B'!D5-(('Airmass-B'!D5-1)*(0.0018161+('Airmass-B'!D5-1)*(0.002875+('Airmass-B'!D5-1)*0.0008083))) -> -1.2207795 | N22: =O22-(INDEX(Stars!$D$1:$D$242, MATCH(A22,Stars!$A$1:$A$242,))+INDEX(Stars!$E$1:$E$242, MATCH(A22,Stars!$A$1:$A$242,))) -> #DIV/0! | O22: =-2.5*LOG10(K22) -> #DIV/0!
D23: Sky deflection | E23: =E22 -> 46033 | J23: =AVERAGE(G23:I23) -> #DIV/0! | L23: =IF(AND(G23=H23,G23=I23),"1000",J23/_xlfn.STDEV.P(G23:I23)) -> 1000
A24: ='Data Entry-V'!A24 -> HD 76757 | B24: ='Data Entry-V'!B24 -> 8.9689 | C24: ='Data Entry-V'!C24 -> 1.5416 | D24: Star deflection | E24: =E23 -> 46033 | J24: =AVERAGE(G24:I24) -> #DIV/0! | K24: =(J24-J25) -> #DIV/0! | L24: =IF(AND(G24=H24,G24=I24),"1000",K24/_xlfn.STDEV.P(G24:I24)) -> 1000 | M24: ='Airmass-B'!D6-(('Airmass-B'!D6-1)*(0.0018161+('Airmass-B'!D6-1)*(0.002875+('Airmass-B'!D6-1)*0.0008083))) -> -1.405163 | N24: =O24-(INDEX(Stars!$D$1:$D$242, MATCH(A24,Stars!$A$1:$A$242,))+INDEX(Stars!$E$1:$E$242, MATCH(A24,Stars!$A$1:$A$242,))) -> #DIV/0! | O24: =-2.5*LOG10(K24) -> #DIV/0!
D25: Sky deflection | E25: =E24 -> 46033 | J25: =AVERAGE(G25:I25) -> #DIV/0! | L25: =IF(AND(G25=H25,G25=I25),"1000",J25/_xlfn.STDEV.P(G25:I25)) -> 1000
M27: kapB= | N27: =(5*(M16*N16+M18*N18+M20*N20+M22*N22+M24*N24)-SUM(M16:M24)*SUM(N16:N24))/(5*(M16^2+M18^2+M20^2+M22^2+M24^2)-((SUM(M16:M24)^2))) -> #DIV/0!
M28: R^2= | N28: =((5*(M16*N16+M18*N18+M20*N20+M22*N22+M24*N24)-SUM(M16:M24)*SUM(N16:N24))/((SQRT((5*(M16^2+M18^2+M20^2+M22^2+M24^2)-(SUM(M16:M24)^2))))*(SQRT((5*(N16^2+N18^2+N20^2+N22^2+N24^2)-((SUM(N16:N24)^2)))))))^2 -> #DIV/0!

Sheet Stars
A1: Star | B1: R.A. (2000.0) | C1: Decl (2000.0) | D1: V | E1: B-V | F1: U-B | G1: Julian date | H1: JD at 0 UT | I1: H | J1: D | K1: D at 0 UT | L1: T | M1: GMST | N1: GMST (0-24) | O1: W | P1: L | Q1: e | R1: Dy | S1: GAST | T1: LST | U1: LST (0-24) | V1: LHA (h) | W1: LHA (°) | X1: LHA (0-360°) | Y1: numerator | Z1: denominator | AA1: azimuth | AB1: Azimuth | AC1: Altitude | AD1: sec | AE1: airmass
A2: HD 34968 | B2: 5.3408 | C2: -21.2398 | D2: 4.7 | E2: -0.05 | F2: -0.11 | G2: =IF($AH$3>0.5,($AH$2+2415019)+((((HOUR($AH$3)*60)+MINUTE($AH$3))/1440+DAY($AH$2))-0.5)-DAY($AH$2),($AH$2+2415019)+((((HOUR($AH$3)*60)+MINUTE($AH$3))/1440+DAY($AH$2))-1.5)-DAY($AH$2)+1) -> 2461051.9 | H2: =IF((G2-ROUNDDOWN(G2,0))<0.5,ROUNDDOWN(G2,0)-0.5,ROUNDDOWN(G2,0)+0.5) -> 2461051.5 | I2: =$AH$3*24 -> 10.5 | J2: =G2-2451545 -> 9506.9375 | K2: =G2-2451545 -> 9506.9375 | L2: =AVERAGE(H2-2451545)/36525 -> 0.26027379 | M2: =6.697374558+(0.065707485828*K2)+(1.0027379093*I2)+(0.0854103*L2)+(0.000025862*L2*L2) -> 641.92532 | N2: =M2-24*(ROUNDDOWN(M2/24,0)) -> 17.925315 | O2: =125.04-0.052954*J2 -> -378.39037 | P2: =280.47+0.98565*J2 -> 9650.9829 | Q2: =23.4393-0.0000004*J2 -> 23.435497 | R2: =-0.000319*SIN(RADIANS(O2))-0.000024*SIN((RADIANS(2*P2))) -> 0.00011668967 | S2: =N2+R2*COS(RADIANS(Q2)) -> 17.925423 | T2: =S2-'Data Entry-V'!$F$9/15 -> 29.556534 | U2: =IF(T2<0,T2+24,IF(T2>24,T2-24,T2)) -> 5.5565336 | V2: =U2-B2 -> 0.21573364 | W2: =V2*15 -> 3.2360047 | X2: =IF(W2<0,W2+360,W2) -> 3.2360047 | Y2: =-SIN(RADIANS(X2)) -> -0.056448914 | Z2: =TAN(RADIANS(C2))*COS(RADIANS('Data Entry-V'!$F$8))-SIN(RADIANS('Data Entry-V'!$F$8))*COS(RADIANS(X2)) -> 0.28744565 | AA2: =DEGREES(ATAN2(Z2,Y2)) -> -11.110426 | AB2: =IF(AA2<0,AA2+360,AA2) -> 348.88957 | AC2: =DEGREES(ASIN((SIN(RADIANS('Data Entry-V'!$F$8))*SIN(RADIANS(C2)))+(COS(RADIANS('Data Entry-V'!$F$8))*COS(RADIANS(C2))*COS(RADIANS((U2-B2)*15))))) -> 74.154902 | AD2: =1/(COS((4*ATAN(1))/2-(AC2*(4*ATAN(1))/180))) -> 1.0394974 | AE2: =IF(AC2>10,AD2-((AD2-1)*(0.0018161+(AD2-1)*(0.002875+(AD2-1)*0.0008083))),"") -> 1.0394211 | AG2: Date of first order extinction determination | AH2: 46033
A3: HD 32309 | B3: 5.0238 | C3: -20.0519 | D3: 4.91 | E3: -0.05 | F3: -0.15 | G3: =IF($AH$3>0.5,($AH$2+2415019)+((((HOUR($AH$3)*60)+MINUTE($AH$3))/1440+DAY($AH$2))-0.5)-DAY($AH$2),($AH$2+2415019)+((((HOUR($AH$3)*60)+MINUTE($AH$3))/1440+DAY($AH$2))-1.5)-DAY($AH$2)+1) -> 2461051.9 | H3: =IF((G3-ROUNDDOWN(G3,0))<0.5,ROUNDDOWN(G3,0)-0.5,ROUNDDOWN(G3,0)+0.5) -> 2461051.5 | I3: =$AH$3*24 -> 10.5 | J3: =G3-2451545 -> 9506.9375 | K3: =G3-2451545 -> 9506.9375 | L3: =AVERAGE(H3-2451545)/36525 -> 0.26027379 | M3: =6.697374558+(0.065707485828*K3)+(1.0027379093*I3)+(0.0854103*L3)+(0.000025862*L3*L3) -> 641.92532 | N3: =M3-24*(ROUNDDOWN(M3/24,0)) -> 17.925315 | O3: =125.04-0.052954*J3 -> -378.39037 | P3: =280.47+0.98565*J3 -> 9650.9829 | Q3: =23.4393-0.0000004*J3 -> 23.435497 | R3: =-0.000319*SIN(RADIANS(O3))-0.000024*SIN((RADIANS(2*P3))) -> 0.00011668967 | S3: =N3+R3*COS(RADIANS(Q3)) -> 17.925423 | T3: =S3-'Data Entry-V'!$F$9/15 -> 29.556534 | U3: =IF(T3<0,T3+24,IF(T3>24,T3-24,T3)) -> 5.5565336 | V3: =U3-B3 -> 0.53273364 | W3: =V3*15 -> 7.9910047 | X3: =IF(W3<0,W3+360,W3) -> 7.9910047 | Y3: =-SIN(RADIANS(X3)) -> -0.13901763 | Z3: =TAN(RADIANS(C3))*COS(RADIANS('Data Entry-V'!$F$8))-SIN(RADIANS('Data Entry-V'!$F$8))*COS(RADIANS(X3)) -> 0.30153143 | AA3: =DEGREES(ATAN2(Z3,Y3)) -> -24.751526 | AB3: =IF(AA3<0,AA3+360,AA3) -> 335.24847 | AC3: =DEGREES(ASIN((SIN(RADIANS('Data Entry-V'!$F$8))*SIN(RADIANS(C3)))+(COS(RADIANS('Data Entry-V'!$F$8))*COS(RADIANS(C3))*COS(RADIANS((U3-B3)*15))))) -> 71.825768 | AD3: =1/(COS((4*ATAN(1))/2-(AC3*(4*ATAN(1))/180))) -> 1.052507 | AE3: =IF(AC3>10,AD3-((AD3-1)*(0.0018161+(AD3-1)*(0.002875+(AD3-1)*0.0008083))),"") -> 1.0524036 | AG3: Time of first order extinction determination | AH3: 0.4375
A4: ksi2 Cma | B4: 6.5843 | C4: -22.9648 | D4: 4.54 | E4: -0.04 | F4: -0.02 | G4: =IF($AH$3>0.5,($AH$2+2415019)+((((HOUR($AH$3)*60)+MINUTE($AH$3))/1440+DAY($AH$2))-0.5)-DAY($AH$2),($AH$2+2415019)+((((HOUR($AH$3)*60)+MINUTE($AH$3))/1440+DAY($AH$2))-1.5)-DAY($AH$2)+1) -> 2461051.9 | H4: =IF((G4-ROUNDDOWN(G4,0))<0.5,ROUNDDOWN(G4,0)-0.5,ROUNDDOWN(G4,0)+0.5) -> 2461051.5 | I4: =$AH$3*24 -> 10.5 | J4: =G4-2451545 -> 9506.9375 | K4: =G4-2451545 -> 9506.9375 | L4: =AVERAGE(H4-2451545)/36525 -> 0.26027379 | M4: =6.697374558+(0.065707485828*K4)+(1.0027379093*I4)+(0.0854103*L4)+(0.000025862*L4*L4) -> 641.92532 | N4: =M4-24*(ROUNDDOWN(M4/24,0)) -> 17.925315 | O4: =125.04-0.052954*J4 -> -378.39037 | P4: =280.47+0.98565*J4 -> 9650.9829 | Q4: =23.4393-0.0000004*J4 -> 23.435497 | R4: =-0.000319*SIN(RADIANS(O4))-0.000024*SIN((RADIANS(2*P4))) -> 0.00011668967 | S4: =N4+R4*COS(RADIANS(Q4)) -> 17.925423 | T4: =S4-'Data Entry-V'!$F$9/15 -> 29.556534 | U4: =IF(T4<0,T4+24,IF(T4>24,T4-24,T4)) -> 5.5565336 | V4: =U4-B4 -> -1.0277664 | W4: =V4*15 -> -15.416495 | X4: =IF(W4<0,W4+360,W4) -> 344.5835 | Y4: =-SIN(RADIANS(X4)) -> 0.26583367 | Z4: =TAN(RADIANS(C4))*COS(RADIANS('Data Entry-V'!$F$8))-SIN(RADIANS('Data Entry-V'!$F$8))*COS(RADIANS(X4)) -> 0.23875692 | AA4: =DEGREES(ATAN2(Z4,Y4)) -> 48.071593 | AB4: =IF(AA4<0,AA4+360,AA4) -> 48.071593 | AC4: =DEGREES(ASIN((SIN(RADIANS('Data Entry-V'!$F$8))*SIN(RADIANS(C4)))+(COS(RADIANS('Data Entry-V'!$F$8))*COS(RADIANS(C4))*COS(RADIANS((U4-B4)*15))))) -> 70.792283 | AD4: =1/(COS((4*ATAN(1))/2-(AC4*(4*ATAN(1))/180))) -> 1.0589495 | AE4: =IF(AC4>10,AD4-((AD4-1)*(0.0018161+(AD4-1)*(0.002875+(AD4-1)*0.0008083))),"") -> 1.0588323
A5: the Lep | B5: 6.1026 | C5: -14.9353 | D5: 4.67 | E5: 0.05 | F5: 0 | G5: =IF($AH$3>0.5,($AH$2+2415019)+((((HOUR($AH$3)*60)+MINUTE($AH$3))/1440+DAY($AH$2))-0.5)-DAY($AH$2),($AH$2+2415019)+((((HOUR($AH$3)*60)+MINUTE($AH$3))/1440+DAY($AH$2))-1.5)-DAY($AH$2)+1) -> 2461051.9 | H5: =IF((G5-ROUNDDOWN(G5,0))<0.5,ROUNDDOWN(G5,0)-0.5,ROUNDDOWN(G5,0)+0.5) -> 2461051.5 | I5: =$AH$3*24 -> 10.5 | J5: =G5-2451545 -> 9506.9375 | K5: =G5-2451545 -> 9506.9375 | L5: =AVERAGE(H5-2451545)/36525 -> 0.26027379 | M5: =6.697374558+(0.065707485828*K5)+(1.0027379093*I5)+(0.0854103*L5)+(0.000025862*L5*L5) -> 641.92532 | N5: =M5-24*(ROUNDDOWN(M5/24,0)) -> 17.925315 | O5: =125.04-0.052954*J5 -> -378.39037 | P5: =280.47+0.98565*J5 -> 9650.9829 | Q5: =23.4393-0.0000004*J5 -> 23.435497 | R5: =-0.000319*SIN(RADIANS(O5))-0.000024*SIN((RADIANS(2*P5))) -> 0.00011668967 | S5: =N5+R5*COS(RADIANS(Q5)) -> 17.925423 | T5: =S5-'Data Entry-V'!$F$9/15 -> 29.556534 | U5: =IF(T5<0,T5+24,IF(T5>24,T5-24,T5)) -> 5.5565336 | V5: =U5-B5 -> -0.54606636 | W5: =V5*15 -> -8.1909953 | X5: =IF(W5<0,W5+360,W5) -> 351.809 | Y5: =-SIN(RADIANS(X5)) -> 0.14247338 | Z5: =TAN(RADIANS(C5))*COS(RADIANS('Data Entry-V'!$F$8))-SIN(RADIANS('Data Entry-V'!$F$8))*COS(RADIANS(X5)) -> 0.37988024 | AA5: =DEGREES(ATAN2(Z5,Y5)) -> 20.558463 | AB5: =IF(AA5<0,AA5+360,AA5) -> 20.558463 | AC5: =DEGREES(ASIN((SIN(RADIANS('Data Entry-V'!$F$8))*SIN(RADIANS(C5)))+(COS(RADIANS('Data Entry-V'!$F$8))*COS(RADIANS(C5))*COS(RADIANS((U5-B5)*15))))) -> 66.920219 | AD5: =1/(COS((4*ATAN(1))/2-(AC5*(4*ATAN(1))/180))) -> 1.0870039 | AE5: =IF(AC5>10,AD5-((AD5-1)*(0.0018161+(AD5-1)*(0.002875+(AD5-1)*0.0008083))),"") -> 1.0868236
A6: HD 39421 | B6: 5.8688 | C6: -9.0367 | D6: 5.95 | E6: 0.1 | F6: 0.08 | G6: =IF($AH$3>0.5,($AH$2+2415019)+((((HOUR($AH$3)*60)+MINUTE($AH$3))/1440+DAY($AH$2))-0.5)-DAY($AH$2),($AH$2+2415019)+((((HOUR($AH$3)*60)+MINUTE($AH$3))/1440+DAY($AH$2))-1.5)-DAY($AH$2)+1) -> 2461051.9 | H6: =IF((G6-ROUNDDOWN(G6,0))<0.5,ROUNDDOWN(G6,0)-0.5,ROUNDDOWN(G6,0)+0.5) -> 2461051.5 | I6: =$AH$3*24 -> 10.5 | J6: =G6-2451545 -> 9506.9375 | K6: =G6-2451545 -> 9506.9375 | L6: =AVERAGE(H6-2451545)/36525 -> 0.26027379 | M6: =6.697374558+(0.065707485828*K6)+(1.0027379093*I6)+(0.0854103*L6)+(0.000025862*L6*L6) -> 641.92532 | N6: =M6-24*(ROUNDDOWN(M6/24,0)) -> 17.925315 | O6: =125.04-0.052954*J6 -> -378.39037 | P6: =280.47+0.98565*J6 -> 9650.9829 | Q6: =23.4393-0.0000004*J6 -> 23.435497 | R6: =-0.000319*SIN(RADIANS(O6))-0.000024*SIN((RADIANS(2*P6))) -> 0.00011668967 | S6: =N6+R6*COS(RADIANS(Q6)) -> 17.925423 | T6: =S6-'Data Entry-V'!$F$9/15 -> 29.556534 | U6: =IF(T6<0,T6+24,IF(T6>24,T6-24,T6)) -> 5.5565336 | V6: =U6-B6 -> -0.31226636 | W6: =V6*15 -> -4.6839953 | X6: =IF(W6<0,W6+360,W6) -> 355.316 | Y6: =-SIN(RADIANS(X6)) -> 0.081660111 | Z6: =TAN(RADIANS(C6))*COS(RADIANS('Data Entry-V'!$F$8))-SIN(RADIANS('Data Entry-V'!$F$8))*COS(RADIANS(X6)) -> 0.47019343 | AA6: =DEGREES(ATAN2(Z6,Y6)) -> 9.8524812 | AB6: =IF(AA6<0,AA6+360,AA6) -> 9.8524812 | AC6: =DEGREES(ASIN((SIN(RADIANS('Data Entry-V'!$F$8))*SIN(RADIANS(C6)))+(COS(RADIANS('Data Entry-V'!$F$8))*COS(RADIANS(C6))*COS(RADIANS((U6-B6)*15))))) -> 61.880738 | AD6: =1/(COS((4*ATAN(1))/2-(AC6*(4*ATAN(1))/180))) -> 1.1338274 | AE6: =IF(AC6>10,AD6-((AD6-1)*(0.0018161+(AD6-1)*(0.002875+(AD6-1)*0.0008083))),"") -> 1.1335309
A7: 49 Ori | B7: 5.6481 | C7: -7.2128 | D7: 4.81 | E7: 0.14 | F7: 0.09 | G7: =IF($AH$3>0.5,($AH$2+2415019)+((((HOUR($AH$3)*60)+MINUTE($AH$3))/1440+DAY($AH$2))-0.5)-DAY($AH$2),($AH$2+2415019)+((((HOUR($AH$3)*60)+MINUTE($AH$3))/1440+DAY($AH$2))-1.5)-DAY($AH$2)+1) -> 2461051.9 | H7: =IF((G7-ROUNDDOWN(G7,0))<0.5,ROUNDDOWN(G7,0)-0.5,ROUNDDOWN(G7,0)+0.5) -> 2461051.5 | I7: =$AH$3*24 -> 10.5 | J7: =G7-2451545 -> 9506.9375 | K7: =G7-2451545 -> 9506.9375 | L7: =AVERAGE(H7-2451545)/36525 -> 0.26027379 | M7: =6.697374558+(0.065707485828*K7)+(1.0027379093*I7)+(0.0854103*L7)+(0.000025862*L7*L7) -> 641.92532 | N7: =M7-24*(ROUNDDOWN(M7/24,0)) -> 17.925315 | O7: =125.04-0.052954*J7 -> -378.39037 | P7: =280.47+0.98565*J7 -> 9650.9829 | Q7: =23.4393-0.0000004*J7 -> 23.435497 | R7: =-0.000319*SIN(RADIANS(O7))-0.000024*SIN((RADIANS(2*P7))) -> 0.00011668967 | S7: =N7+R7*COS(RADIANS(Q7)) -> 17.925423 | T7: =S7-'Data Entry-V'!$F$9/15 -> 29.556534 | U7: =IF(T7<0,T7+24,IF(T7>24,T7-24,T7)) -> 5.5565336 | V7: =U7-B7 -> -0.091566357 | W7: =V7*15 -> -1.3734953 | X7: =IF(W7<0,W7+360,W7) -> 358.6265 | Y7: =-SIN(RADIANS(X7)) -> 0.02396972 | Z7: =TAN(RADIANS(C7))*COS(RADIANS('Data Entry-V'!$F$8))-SIN(RADIANS('Data Entry-V'!$F$8))*COS(RADIANS(X7)) -> 0.49802358 | AA7: =DEGREES(ATAN2(Z7,Y7)) -> 2.7555017 | AB7: =IF(AA7<0,AA7+360,AA7) -> 2.7555017 | AC7: =DEGREES(ASIN((SIN(RADIANS('Data Entry-V'!$F$8))*SIN(RADIANS(C7)))+(COS(RADIANS('Data Entry-V'!$F$8))*COS(RADIANS(C7))*COS(RADIANS((U7-B7)*15))))) -> 60.35303 | AD7: =1/(COS((4*ATAN(1))/2-(AC7*(4*ATAN(1))/180))) -> 1.1506292 | AE7: =IF(AC7>10,AD7-((AD7-1)*(0.0018161+(AD7-1)*(0.002875+(AD7-1)*0.0008083))),"") -> 1.1502876
A8: HD 42536 | B8: 6.1837 | C8: -6.7542 | D8: 6.14 | E8: 0.01 | F8: 0.03 | G8: =IF($AH$3>0.5,($AH$2+2415019)+((((HOUR($AH$3)*60)+MINUTE($AH$3))/1440+DAY($AH$2))-0.5)-DAY($AH$2),($AH$2+2415019)+((((HOUR($AH$3)*60)+MINUTE($AH$3))/1440+DAY($AH$2))-1.5)-DAY($AH$2)+1) -> 2461051.9 | H8: =IF((G8-ROUNDDOWN(G8,0))<0.5,ROUNDDOWN(G8,0)-0.5,ROUNDDOWN(G8,0)+0.5) -> 2461051.5 | I8: =$AH$3*24 -> 10.5 | J8: =G8-2451545 -> 9506.9375 | K8: =G8-2451545 -> 9506.9375 | L8: =AVERAGE(H8-2451545)/36525 -> 0.26027379 | M8: =6.697374558+(0.065707485828*K8)+(1.0027379093*I8)+(0.0854103*L8)+(0.000025862*L8*L8) -> 641.92532 | N8: =M8-24*(ROUNDDOWN(M8/24,0)) -> 17.925315 | O8: =125.04-0.052954*J8 -> -378.39037 | P8: =280.47+0.98565*J8 -> 9650.9829 | Q8: =23.4393-0.0000004*J8 -> 23.435497 | R8: =-0.000319*SIN(RADIANS(O8))-0.000024*SIN((RADIANS(2*P8))) -> 0.00011668967 | S8: =N8+R8*COS(RADIANS(Q8)) -> 17.925423 | T8: =S8-'Data Entry-V'!$F$9/15 -> 29.556534 | U8: =IF(T8<0,T8+24,IF(T8>24,T8-24,T8)) -> 5.5565336 | V8: =U8-B8 -> -0.62716636 | W8: =V8*15 -> -9.4074953 | X8: =IF(W8<0,W8+360,W8) -> 350.5925 | Y8: =-SIN(RADIANS(X8)) -> 0.16345502 | Z8: =TAN(RADIANS(C8))*COS(RADIANS('Data Entry-V'!$F$8))-SIN(RADIANS('Data Entry-V'!$F$8))*COS(RADIANS(X8)) -> 0.49663565 | AA8: =DEGREES(ATAN2(Z8,Y8)) -> 18.217648 | AB8: =IF(AA8<0,AA8+360,AA8) -> 18.217648 | AC8: =DEGREES(ASIN((SIN(RADIANS('Data Entry-V'!$F$8))*SIN(RADIANS(C8)))+(COS(RADIANS('Data Entry-V'!$F$8))*COS(RADIANS(C8))*COS(RADIANS((U8-B8)*15))))) -> 58.72045 | AD8: =1/(COS((4*ATAN(1))/2-(AC8*(4*ATAN(1))/180))) -> 1.1700776 | AE8: =IF(AC8>10,AD8-((AD8-1)*(0.0018161+(AD8-1)*(0.002875+(AD8-1)*0.0008083))),"") -> 1.1696815
A9: HD 45830 | B9: 6.4458 | C9: -7.5119 | D9: 6.26 | E9: -0.03 | F9: -0.1 | G9: =IF($AH$3>0.5,($AH$2+2415019)+((((HOUR($AH$3)*60)+MINUTE($AH$3))/1440+DAY($AH$2))-0.5)-DAY($AH$2),($AH$2+2415019)+((((HOUR($AH$3)*60)+MINUTE($AH$3))/1440+DAY($AH$2))-1.5)-DAY($AH$2)+1) -> 2461051.9 | H9: =IF((G9-ROUNDDOWN(G9,0))<0.5,ROUNDDOWN(G9,0)-0.5,ROUNDDOWN(G9,0)+0.5) -> 2461051.5 | I9: =$AH$3*24 -> 10.5 | J9: =G9-2451545 -> 9506.9375 | K9: =G9-2451545 -> 9506.9375 | L9: =AVERAGE(H9-2451545)/36525 -> 0.26027379 | M9: =6.697374558+(0.065707485828*K9)+(1.0027379093*I9)+(0.0854103*L9)+(0.000025862*L9*L9) -> 641.92532 | N9: =M9-24*(ROUNDDOWN(M9/24,0)) -> 17.925315 | O9: =125.04-0.052954*J9 -> -378.39037 | P9: =280.47+0.98565*J9 -> 9650.9829 | Q9: =23.4393-0.0000004*J9 -> 23.435497 | R9: =-0.000319*SIN(RADIANS(O9))-0.000024*SIN((RADIANS(2*P9))) -> 0.00011668967 | S9: =N9+R9*COS(RADIANS(Q9)) -> 17.925423 | T9: =S9-'Data Entry-V'!$F$9/15 -> 29.556534 | U9: =IF(T9<0,T9+24,IF(T9>24,T9-24,T9)) -> 5.5565336 | V9: =U9-B9 -> -0.88926636 | W9: =V9*15 -> -13.338995 | X9: =IF(W9<0,W9+360,W9) -> 346.661 | Y9: =-SIN(RADIANS(X9)) -> 0.23071203 | Z9: =TAN(RADIANS(C9))*COS(RADIANS('Data Entry-V'!$F$8))-SIN(RADIANS('Data Entry-V'!$F$8))*COS(RADIANS(X9)) -> 0.47777486 | AA9: =DEGREES(ATAN2(Z9,Y9)) -> 25.775366 | AB9: =IF(AA9<0,AA9+360,AA9) -> 25.775366 | AC9: =DEGREES(ASIN((SIN(RADIANS('Data Entry-V'!$F$8))*SIN(RADIANS(C9)))+(COS(RADIANS('Data Entry-V'!$F$8))*COS(RADIANS(C9))*COS(RADIANS((U9-B9)*15))))) -> 58.263784 | AD9: =1/(COS((4*ATAN(1))/2-(AC9*(4*ATAN(1))/180))) -> 1.1758083 | AE9: =IF(AC9>10,AD9-((AD9-1)*(0.0018161+(AD9-1)*(0.002875+(AD9-1)*0.0008083))),"") -> 1.1753957
A10: HD 39927 | B10: 5.9265 | C10: -4.7886 | D10: 6.2 | E10: 0.05 | F10: 0.06 | G10: =IF($AH$3>0.5,($AH$2+2415019)+((((HOUR($AH$3)*60)+MINUTE($AH$3))/1440+DAY($AH$2))-0.5)-DAY($AH$2),($AH$2+2415019)+((((HOUR($AH$3)*60)+MINUTE($AH$3))/1440+DAY($AH$2))-1.5)-DAY($AH$2)+1) -> 2461051.9 | H10: =IF((G10-ROUNDDOWN(G10,0))<0.5,ROUNDDOWN(G10,0)-0.5,ROUNDDOWN(G10,0)+0.5) -> 2461051.5 | I10: =$AH$3*24 -> 10.5 | J10: =G10-2451545 -> 9506.9375 | K10: =G10-2451545 -> 9506.9375 | L10: =AVERAGE(H10-2451545)/36525 -> 0.26027379 | M10: =6.697374558+(0.065707485828*K10)+(1.0027379093*I10)+(0.0854103*L10)+(0.000025862*L10*L10) -> 641.92532 | N10: =M10-24*(ROUNDDOWN(M10/24,0)) -> 17.925315 | O10: =125.04-0.052954*J10 -> -378.39037 | P10: =280.47+0.98565*J10 -> 9650.9829 | Q10: =23.4393-0.0000004*J10 -> 23.435497 | R10: =-0.000319*SIN(RADIANS(O10))-0.000024*SIN((RADIANS(2*P10))) -> 0.00011668967 | S10: =N10+R10*COS(RADIANS(Q10)) -> 17.925423 | T10: =S10-'Data Entry-V'!$F$9/15 -> 29.556534 | U10: =IF(T10<0,T10+24,IF(T10>24,T10-24,T10)) -> 5.5565336 | V10: =U10-B10 -> -0.36996636 | W10: =V10*15 -> -5.5494953 | X10: =IF(W10<0,W10+360,W10) -> 354.4505 | Y10: =-SIN(RADIANS(X10)) -> 0.096705596 | Z10: =TAN(RADIANS(C10))*COS(RADIANS('Data Entry-V'!$F$8))-SIN(RADIANS('Data Entry-V'!$F$8))*COS(RADIANS(X10)) -> 0.52962991 | AA10: =DEGREES(ATAN2(Z10,Y10)) -> 10.347697 | AB10: =IF(AA10<0,AA10+360,AA10) -> 10.347697 | AC10: =DEGREES(ASIN((SIN(RADIANS('Data Entry-V'!$F$8))*SIN(RADIANS(C10)))+(COS(RADIANS('Data Entry-V'!$F$8))*COS(RADIANS(C10))*COS(RADIANS((U10-B10)*15))))) -> 57.553826 | AD10: =1/(COS((4*ATAN(1))/2-(AC10*(4*ATAN(1))/180))) -> 1.1849804 | AE10: =IF(AC10>10,AD10-((AD10-1)*(0.0018161+(AD10-1)*(0.002875+(AD10-1)*0.0008083))),"") -> 1.1845409
A11: HD 16754 | B11: 2.6633 | C11: -42.8918 | D11: 4.74 | E11: 0.06 | F11: 0.06 | G11: =IF($AH$3>0.5,($AH$2+2415019)+((((HOUR($AH$3)*60)+MINUTE($AH$3))/1440+DAY($AH$2))-0.5)-DAY($AH$2),($AH$2+2415019)+((((HOUR($AH$3)*60)+MINUTE($AH$3))/1440+DAY($AH$2))-1.5)-DAY($AH$2)+1) -> 2461051.9 | H11: =IF((G11-ROUNDDOWN(G11,0))<0.5,ROUNDDOWN(G11,0)-0.5,ROUNDDOWN(G11,0)+0.5) -> 2461051.5 | I11: =$AH$3*24 -> 10.5 | J11: =G11-2451545 -> 9506.9375 | K11: =G11-2451545 -> 9506.9375 | L11: =AVERAGE(H11-2451545)/36525 -> 0.26027379 | M11: =6.697374558+(0.065707485828*K11)+(1.0027379093*I11)+(0.0854103*L11)+(0.000025862*L11*L11) -> 641.92532 | N11: =M11-24*(ROUNDDOWN(M11/24,0)) -> 17.925315 | O11: =125.04-0.052954*J11 -> -378.39037 | P11: =280.47+0.98565*J11 -> 9650.9829 | Q11: =23.4393-0.0000004*J11 -> 23.435497 | R11: =-0.000319*SIN(RADIANS(O11))-0.000024*SIN((RADIANS(2*P11))) -> 0.00011668967 | S11: =N11+R11*COS(RADIANS(Q11)) -> 17.925423 | T11: =S11-'Data Entry-V'!$F$9/15 -> 29.556534 | U11: =IF(T11<0,T11+24,IF(T11>24,T11-24,T11)) -> 5.5565336 | V11: =U11-B11 -> 2.8932336 | W11: =V11*15 -> 43.398505 | X11: =IF(W11<0,W11+360,W11) -> 43.398505 | Y11: =-SIN(RADIANS(X11)) -> -0.68706855 | Z11: =TAN(RADIANS(C11))*COS(RADIANS('Data Entry-V'!$F$8))-SIN(RADIANS('Data Entry-V'!$F$8))*COS(RADIANS(X11)) -> -0.30796358 | AA11: =DEGREES(ATAN2(Z11,Y11)) -> -114.14327 | AB11: =IF(AA11<0,AA11+360,AA11) -> 245.85673 | AC11: =DEGREES(ASIN((SIN(RADIANS('Data Entry-V'!$F$8))*SIN(RADIANS(C11)))+(COS(RADIANS('Data Entry-V'!$F$8))*COS(RADIANS(C11))*COS(RADIANS((U11-B11)*15))))) -> 56.521266 | AD11: =1/(COS((4*ATAN(1))/2-(AC11*(4*ATAN(1))/180))) -> 1.1989105 | AE11: =IF(AC11>10,AD11-((AD11-1)*(0.0018161+(AD11-1)*(0.002875+(AD11-1)*0.0008083))),"") -> 1.1984291
A12: HD 36058 | B12: 5.4825 | C12: -3.3074 | D12: 6.38 | E12: -0.01 | F12: -0.06 | G12: =IF($AH$3>0.5,($AH$2+2415019)+((((HOUR($AH$3)*60)+MINUTE($AH$3))/1440+DAY($AH$2))-0.5)-DAY($AH$2),($AH$2+2415019)+((((HOUR($AH$3)*60)+MINUTE($AH$3))/1440+DAY($AH$2))-1.5)-DAY($AH$2)+1) -> 2461051.9 | H12: =IF((G12-ROUNDDOWN(G12,0))<0.5,ROUNDDOWN(G12,0)-0.5,ROUNDDOWN(G12,0)+0.5) -> 2461051.5 | I12: =$AH$3*24 -> 10.5 | J12: =G12-2451545 -> 9506.9375 | K12: =G12-2451545 -> 9506.9375 | L12: =AVERAGE(H12-2451545)/36525 -> 0.26027379 | M12: =6.697374558+(0.065707485828*K12)+(1.0027379093*I12)+(0.0854103*L12)+(0.000025862*L12*L12) -> 641.92532 | N12: =M12-24*(ROUNDDOWN(M12/24,0)) -> 17.925315 | O12: =125.04-0.052954*J12 -> -378.39037 | P12: =280.47+0.98565*J12 -> 9650.9829 | Q12: =23.4393-0.0000004*J12 -> 23.435497 | R12: =-0.000319*SIN(RADIANS(O12))-0.000024*SIN((RADIANS(2*P12))) -> 0.00011668967 | S12: =N12+R12*COS(RADIANS(Q12)) -> 17.925423 | T12: =S12-'Data Entry-V'!$F$9/15 -> 29.556534 | U12: =IF(T12<0,T12+24,IF(T12>24,T12-24,T12)) -> 5.5565336 | V12: =U12-B12 -> 0.074033643 | W12: =V12*15 -> 1.1105047 | X12: =IF(W12<0,W12+360,W12) -> 1.1105047 | Y12: =-SIN(RADIANS(X12)) -> -0.019380749 | Z12: =TAN(RADIANS(C12))*COS(RADIANS('Data Entry-V'!$F$8))-SIN(RADIANS('Data Entry-V'!$F$8))*COS(RADIANS(X12)) -> 0.55312325 | AA12: =DEGREES(ATAN2(Z12,Y12)) -> -2.0067517 | AB12: =IF(AA12<0,AA12+360,AA12) -> 357.99325 | AC12: =DEGREES(ASIN((SIN(RADIANS('Data Entry-V'!$F$8))*SIN(RADIANS(C12)))+(COS(RADIANS('Data Entry-V'!$F$8))*COS(RADIANS(C12))*COS(RADIANS((U12-B12)*15))))) -> 56.458501 | AD12: =1/(COS((4*ATAN(1))/2-(AC12*(4*ATAN(1))/180))) -> 1.1997804 | AE12: =IF(AC12>10,AD12-((AD12-1)*(0.0018161+(AD12-1)*(0.002875+(AD12-1)*0.0008083))),"") -> 1.1992964
A13: HD 44756 | B13: 6.3897 | C13: -4.6605 | D13: 6.66 | E13: 0.06 | F13: 0 | G13: =IF($AH$3>0.5,($AH$2+2415019)+((((HOUR($AH$3)*60)+MINUTE($AH$3))/1440+DAY($AH$2))-0.5)-DAY($AH$2),($AH$2+2415019)+((((HOUR($AH$3)*60)+MINUTE($AH$3))/1440+DAY($AH$2))-1.5)-DAY($AH$2)+1) -> 2461051.9 | H13: =IF((G13-ROUNDDOWN(G13,0))<0.5,ROUNDDOWN(G13,0)-0.5,ROUNDDOWN(G13,0)+0.5) -> 2461051.5 | I13: =$AH$3*24 -> 10.5 | J13: =G13-2451545 -> 9506.9375 | K13: =G13-2451545 -> 9506.9375 | L13: =AVERAGE(H13-2451545)/36525 -> 0.26027379 | M13: =6.697374558+(0.065707485828*K13)+(1.0027379093*I13)+(0.0854103*L13)+(0.000025862*L13*L13) -> 641.92532 | N13: =M13-24*(ROUNDDOWN(M13/24,0)) -> 17.925315 | O13: =125.04-0.052954*J13 -> -378.39037 | P13: =280.47+0.98565*J13 -> 9650.9829 | Q13: =23.4393-0.0000004*J13 -> 23.435497 | R13: =-0.000319*SIN(RADIANS(O13))-0.000024*SIN((RADIANS(2*P13))) -> 0.00011668967 | S13: =N13+R13*COS(RADIANS(Q13)) -> 17.925423 | T13: =S13-'Data Entry-V'!$F$9/15 -> 29.556534 | U13: =IF(T13<0,T13+24,IF(T13>24,T13-24,T13)) -> 5.5565336 | V13: =U13-B13 -> -0.83316636 | W13: =V13*15 -> -12.497495 | X13: =IF(W13<0,W13+360,W13) -> 347.5025 | Y13: =-SIN(RADIANS(X13)) -> 0.21639694 | Z13: =TAN(RADIANS(C13))*COS(RADIANS('Data Entry-V'!$F$8))-SIN(RADIANS('Data Entry-V'!$F$8))*COS(RADIANS(X13)) -> 0.52003677 | AA13: =DEGREES(ATAN2(Z13,Y13)) -> 22.5931 | AB13: =IF(AA13<0,AA13+360,AA13) -> 22.5931 | AC13: =DEGREES(ASIN((SIN(RADIANS('Data Entry-V'!$F$8))*SIN(RADIANS(C13)))+(COS(RADIANS('Data Entry-V'!$F$8))*COS(RADIANS(C13))*COS(RADIANS((U13-B13)*15))))) -> 55.847242 | AD13: =1/(COS((4*ATAN(1))/2-(AC13*(4*ATAN(1))/180))) -> 1.2083953 | AE13: =IF(AC13>10,AD13-((AD13-1)*(0.0018161+(AD13-1)*(0.002875+(AD13-1)*0.0008083))),"") -> 1.2078847
A14: HD 25910 | B14: 4.099 | C14: -8.8561 | D14: 6.26 | E14: 0.06 | F14: 0.08 | G14: =IF($AH$3>0.5,($AH$2+2415019)+((((HOUR($AH$3)*60)+MINUTE($AH$3))/1440+DAY($AH$2))-0.5)-DAY($AH$2),($AH$2+2415019)+((((HOUR($AH$3)*60)+MINUTE($AH$3))/1440+DAY($AH$2))-1.5)-DAY($AH$2)+1) -> 2461051.9 | H14: =IF((G14-ROUNDDOWN(G14,0))<0.5,ROUNDDOWN(G14,0)-0.5,ROUNDDOWN(G14,0)+0.5) -> 2461051.5 | I14: =$AH$3*24 -> 10.5 | J14: =G14-2451545 -> 9506.9375 | K14: =G14-2451545 -> 9506.9375 | L14: =AVERAGE(H14-2451545)/36525 -> 0.26027379 | M14: =6.697374558+(0.065707485828*K14)+(1.0027379093*I14)+(0.0854103*L14)+(0.000025862*L14*L14) -> 641.92532 | N14: =M14-24*(ROUNDDOWN(M14/24,0)) -> 17.925315 | O14: =125.04-0.052954*J14 -> -378.39037 | P14: =280.47+0.98565*J14 -> 9650.9829 | Q14: =23.4393-0.0000004*J14 -> 23.435497 | R14: =-0.000319*SIN(RADIANS(O14))-0.000024*SIN((RADIANS(2*P14))) -> 0.00011668967 | S14: =N14+R14*COS(RADIANS(Q14)) -> 17.925423 | T14: =S14-'Data Entry-V'!$F$9/15 -> 29.556534 | U14: =IF(T14<0,T14+24,IF(T14>24,T14-24,T14)) -> 5.5565336 | V14: =U14-B14 -> 1.4575336 | W14: =V14*15 -> 21.863005 | X14: =IF(W14<0,W14+360,W14) -> 21.863005 | Y14: =-SIN(RADIANS(X14)) -> -0.37238861 | Z14: =TAN(RADIANS(C14))*COS(RADIANS('Data Entry-V'!$F$8))-SIN(RADIANS('Data Entry-V'!$F$8))*COS(RADIANS(X14)) -> 0.43166383 | AA14: =DEGREES(ATAN2(Z14,Y14)) -> -40.783748 | AB14: =IF(AA14<0,AA14+360,AA14) -> 319.21625 | AC14: =DEGREES(ASIN((SIN(RADIANS('Data Entry-V'!$F$8))*SIN(RADIANS(C14)))+(COS(RADIANS('Data Entry-V'!$F$8))*COS(RADIANS(C14))*COS(RADIANS((U14-B14)*15))))) -> 55.71587 | AD14: =1/(COS((4*ATAN(1))/2-(AC14*(4*ATAN(1))/180))) -> 1.2102811 | AE14: =IF(AC14>10,AD14-((AD14-1)*(0.0018161+(AD14-1)*(0.002875+(AD14-1)*0.0008083))),"") -> 1.2097645
A15: HD 73634 | B15: 8.6274 | C15: -42.9891 | D15: 4.14 | E15: 0.1 | F15: 0.12 | G15: =IF($AH$3>0.5,($AH$2+2415019)+((((HOUR($AH$3)*60)+MINUTE($AH$3))/1440+DAY($AH$2))-0.5)-DAY($AH$2),($AH$2+2415019)+((((HOUR($AH$3)*60)+MINUTE($AH$3))/1440+DAY($AH$2))-1.5)-DAY($AH$2)+1) -> 2461051.9 | H15: =IF((G15-ROUNDDOWN(G15,0))<0.5,ROUNDDOWN(G15,0)-0.5,ROUNDDOWN(G15,0)+0.5) -> 2461051.5 | I15: =$AH$3*24 -> 10.5 | J15: =G15-2451545 -> 9506.9375 | K15: =G15-2451545 -> 9506.9375 | L15: =AVERAGE(H15-2451545)/36525 -> 0.26027379 | M15: =6.697374558+(0.065707485828*K15)+(1.0027379093*I15)+(0.0854103*L15)+(0.000025862*L15*L15) -> 641.92532 | N15: =M15-24*(ROUNDDOWN(M15/24,0)) -> 17.925315 | O15: =125.04-0.052954*J15 -> -378.39037 | P15: =280.47+0.98565*J15 -> 9650.9829 | Q15: =23.4393-0.0000004*J15 -> 23.435497 | R15: =-0.000319*SIN(RADIANS(O15))-0.000024*SIN((RADIANS(2*P15))) -> 0.00011668967 | S15: =N15+R15*COS(RADIANS(Q15)) -> 17.925423 | T15: =S15-'Data Entry-V'!$F$9/15 -> 29.556534 | U15: =IF(T15<0,T15+24,IF(T15>24,T15-24,T15)) -> 5.5565336 | V15: =U15-B15 -> -3.0708664 | W15: =V15*15 -> -46.062995 | X15: =IF(W15<0,W15+360,W15) -> 313.937 | Y15: =-SIN(RADIANS(X15)) -> 0.72010313 | Z15: =TAN(RADIANS(C15))*COS(RADIANS('Data Entry-V'!$F$8))-SIN(RADIANS('Data Entry-V'!$F$8))*COS(RADIANS(X15)) -> -0.33011845 | AA15: =DEGREES(ATAN2(Z15,Y15)) -> 114.62825 | AB15: =IF(AA15<0,AA15+360,AA15) -> 114.62825 | AC15: =DEGREES(ASIN((SIN(RADIANS('Data Entry-V'!$F$8))*SIN(RADIANS(C15)))+(COS(RADIANS('Data Entry-V'!$F$8))*COS(RADIANS(C15))*COS(RADIANS((U15-B15)*15))))) -> 54.587698 | AD15: =1/(COS((4*ATAN(1))/2-(AC15*(4*ATAN(1))/180))) -> 1.2269888 | AE15: =IF(AC15>10,AD15-((AD15-1)*(0.0018161+(AD15-1)*(0.002875+(AD15-1)*0.0008083))),"") -> 1.2264189
... A39: pi2 Ori | B39: 4.8435 | C39: 8.9 | D39: 4.35 | E39: 0.01 | F39: 0.03 | G39: =IF($AH$3>0.5,($AH$2+2415019)+((((HOUR($AH$3)*60)+MINUTE($AH$3))/1440+DAY($AH$2))-0.5)-DAY($AH$2),($AH$2+2415019)+((((HOUR($AH$3)*60)+MINUTE($AH$3))/1440+DAY($AH$2))-1.5)-DAY($AH$2)+1) -> 2461051.9 | H39: =IF((G39-ROUNDDOWN(G39,0))<0.5,ROUNDDOWN(G39,0)-0.5,ROUNDDOWN(G39,0)+0.5) -> 2461051.5 | I39: =$AH$3*24 -> 10.5 | J39: =G39-2451545 -> 9506.9375 | K39: =G39-2451545 -> 9506.9375 | L39: =AVERAGE(H39-2451545)/36525 -> 0.26027379 | M39: =6.697374558+(0.065707485828*K39)+(1.0027379093*I39)+(0.0854103*L39)+(0.000025862*L39*L39) -> 641.92532 | N39: =M39-24*(ROUNDDOWN(M39/24,0)) -> 17.925315 | O39: =125.04-0.052954*J39 -> -378.39037 | P39: =280.47+0.98565*J39 -> 9650.9829 | Q39: =23.4393-0.0000004*J39 -> 23.435497 | R39: =-0.000319*SIN(RADIANS(O39))-0.000024*SIN((RADIANS(2*P39))) -> 0.00011668967 | S39: =N39+R39*COS(RADIANS(Q39)) -> 17.925423 | T39: =S39-'Data Entry-V'!$F$9/15 -> 29.556534 | U39: =IF(T39<0,T39+24,IF(T39>24,T39-24,T39)) -> 5.5565336 | V39: =U39-B39 -> 0.71303364 | W39: =V39*15 -> 10.695505 | X39: =IF(W39<0,W39+360,W39) -> 10.695505 | Y39: =-SIN(RADIANS(X39)) -> -0.18558952 | Z39: =TAN(RADIANS(C39))*COS(RADIANS('Data Entry-V'!$F$8))-SIN(RADIANS('Data Entry-V'!$F$8))*COS(RADIANS(X39)) -> 0.71441122 | AA39: =DEGREES(ATAN2(Z39,Y39)) -> -14.562392 | AB39: =IF(AA39<0,AA39+360,AA39) -> 345.43761 | AC39: =DEGREES(ASIN((SIN(RADIANS('Data Entry-V'!$F$8))*SIN(RADIANS(C39)))+(COS(RADIANS('Data Entry-V'!$F$8))*COS(RADIANS(C39))*COS(RADIANS((U39-B39)*15))))) -> 43.177552 | AD39: =1/(COS((4*ATAN(1))/2-(AC39*(4*ATAN(1))/180))) -> 1.4614297 | AE39: =IF(AC39>10,AD39-((AD39-1)*(0.0018161+(AD39-1)*(0.002875+(AD39-1)*0.0008083))),"") -> 1.4599001
A40: rho Cet | B40: 2.5325 | C40: -12.2905 | D40: 4.89 | E40: =-0.02 -> -0.02 | F40: -0.04 | G40: =IF($AH$3>0.5,($AH$2+2415019)+((((HOUR($AH$3)*60)+MINUTE($AH$3))/1440+DAY($AH$2))-0.5)-DAY($AH$2),($AH$2+2415019)+((((HOUR($AH$3)*60)+MINUTE($AH$3))/1440+DAY($AH$2))-1.5)-DAY($AH$2)+1) -> 2461051.9 | H40: =IF((G40-ROUNDDOWN(G40,0))<0.5,ROUNDDOWN(G40,0)-0.5,ROUNDDOWN(G40,0)+0.5) -> 2461051.5 | I40: =$AH$3*24 -> 10.5 | J40: =G40-2451545 -> 9506.9375 | K40: =G40-2451545 -> 9506.9375 | L40: =AVERAGE(H40-2451545)/36525 -> 0.26027379 | M40: =6.697374558+(0.065707485828*K40)+(1.0027379093*I40)+(0.0854103*L40)+(0.000025862*L40*L40) -> 641.92532 | N40: =M40-24*(ROUNDDOWN(M40/24,0)) -> 17.925315 | O40: =125.04-0.052954*J40 -> -378.39037 | P40: =280.47+0.98565*J40 -> 9650.9829 | Q40: =23.4393-0.0000004*J40 -> 23.435497 | R40: =-0.000319*SIN(RADIANS(O40))-0.000024*SIN((RADIANS(2*P40))) -> 0.00011668967 | S40: =N40+R40*COS(RADIANS(Q40)) -> 17.925423 | T40: =S40-'Data Entry-V'!$F$9/15 -> 29.556534 | U40: =IF(T40<0,T40+24,IF(T40>24,T40-24,T40)) -> 5.5565336 | V40: =U40-B40 -> 3.0240336 | W40: =V40*15 -> 45.360505 | X40: =IF(W40<0,W40+360,W40) -> 45.360505 | Y40: =-SIN(RADIANS(X40)) -> -0.71154187 | Z40: =TAN(RADIANS(C40))*COS(RADIANS('Data Entry-V'!$F$8))-SIN(RADIANS('Data Entry-V'!$F$8))*COS(RADIANS(X40)) -> 0.24685477 | AA40: =DEGREES(ATAN2(Z40,Y40)) -> -70.866838 | AB40: =IF(AA40<0,AA40+360,AA40) -> 289.13316 | AC40: =DEGREES(ASIN((SIN(RADIANS('Data Entry-V'!$F$8))*SIN(RADIANS(C40)))+(COS(RADIANS('Data Entry-V'!$F$8))*COS(RADIANS(C40))*COS(RADIANS((U40-B40)*15))))) -> 42.617976 | AD40: =1/(COS((4*ATAN(1))/2-(AC40*(4*ATAN(1))/180))) -> 1.4768717 | AE40: =IF(AC40>10,AD40-((AD40-1)*(0.0018161+(AD40-1)*(0.002875+(AD40-1)*0.0008083))),"") -> 1.4752642
A41: pi1 Ori | B41: 4.9149 | C41: 10.1508 | D41: 4.66 | E41: 0.08 | F41: 0.08 | G41: =IF($AH$3>0.5,($AH$2+2415019)+((((HOUR($AH$3)*60)+MINUTE($AH$3))/1440+DAY($AH$2))-0.5)-DAY($AH$2),($AH$2+2415019)+((((HOUR($AH$3)*60)+MINUTE($AH$3))/1440+DAY($AH$2))-1.5)-DAY($AH$2)+1) -> 2461051.9 | H41: =IF((G41-ROUNDDOWN(G41,0))<0.5,ROUNDDOWN(G41,0)-0.5,ROUNDDOWN(G41,0)+0.5) -> 2461051.5 | I41: =$AH$3*24 -> 10.5 | J41: =G41-2451545 -> 9506.9375 | K41: =G41-2451545 -> 9506.9375 | L41: =AVERAGE(H41-2451545)/36525 -> 0.26027379 | M41: =6.697374558+(0.065707485828*K41)+(1.0027379093*I41)+(0.0854103*L41)+(0.000025862*L41*L41) -> 641.92532 | N41: =M41-24*(ROUNDDOWN(M41/24,0)) -> 17.925315 | O41: =125.04-0.052954*J41 -> -378.39037 | P41: =280.47+0.98565*J41 -> 9650.9829 | Q41: =23.4393-0.0000004*J41 -> 23.435497 | R41: =-0.000319*SIN(RADIANS(O41))-0.000024*SIN((RADIANS(2*P41))) -> 0.00011668967 | S41: =N41+R41*COS(RADIANS(Q41)) -> 17.925423 | T41: =S41-'Data Entry-V'!$F$9/15 -> 29.556534 | U41: =IF(T41<0,T41+24,IF(T41>24,T41-24,T41)) -> 5.5565336 | V41: =U41-B41 -> 0.64163364 | W41: =V41*15 -> 9.6245047 | X41: =IF(W41<0,W41+360,W41) -> 9.6245047 | Y41: =-SIN(RADIANS(X41)) -> -0.16719043 | Z41: =TAN(RADIANS(C41))*COS(RADIANS('Data Entry-V'!$F$8))-SIN(RADIANS('Data Entry-V'!$F$8))*COS(RADIANS(X41)) -> 0.73435346 | AA41: =DEGREES(ATAN2(Z41,Y41)) -> -12.825921 | AB41: =IF(AA41<0,AA41+360,AA41) -> 347.17408 | AC41: =DEGREES(ASIN((SIN(RADIANS('Data Entry-V'!$F$8))*SIN(RADIANS(C41)))+(COS(RADIANS('Data Entry-V'!$F$8))*COS(RADIANS(C41))*COS(RADIANS((U41-B41)*15))))) -> 42.15291 | AD41: =1/(COS((4*ATAN(1))/2-(AC41*(4*ATAN(1))/180))) -> 1.4900653 | AE41: =IF(AC41>10,AD41-((AD41-1)*(0.0018161+(AD41-1)*(0.002875+(AD41-1)*0.0008083))),"") -> 1.4883897
A42: HD 55111 | B42: 7.1976 | C42: 5.6547 | D42: 6.08 | E42: -0.02 | F42: -0.05 | G42: =IF($AH$3>0.5,($AH$2+2415019)+((((HOUR($AH$3)*60)+MINUTE($AH$3))/1440+DAY($AH$2))-0.5)-DAY($AH$2),($AH$2+2415019)+((((HOUR($AH$3)*60)+MINUTE($AH$3))/1440+DAY($AH$2))-1.5)-DAY($AH$2)+1) -> 2461051.9 | H42: =IF((G42-ROUNDDOWN(G42,0))<0.5,ROUNDDOWN(G42,0)-0.5,ROUNDDOWN(G42,0)+0.5) -> 2461051.5 | I42: =$AH$3*24 -> 10.5 | J42: =G42-2451545 -> 9506.9375 | K42: =G42-2451545 -> 9506.9375 | L42: =AVERAGE(H42-2451545)/36525 -> 0.26027379 | M42: =6.697374558+(0.065707485828*K42)+(1.0027379093*I42)+(0.0854103*L42)+(0.000025862*L42*L42) -> 641.92532 | N42: =M42-24*(ROUNDDOWN(M42/24,0)) -> 17.925315 | O42: =125.04-0.052954*J42 -> -378.39037 | P42: =280.47+0.98565*J42 -> 9650.9829 | Q42: =23.4393-0.0000004*J42 -> 23.435497 | R42: =-0.000319*SIN(RADIANS(O42))-0.000024*SIN((RADIANS(2*P42))) -> 0.00011668967 | S42: =N42+R42*COS(RADIANS(Q42)) -> 17.925423 | T42: =S42-'Data Entry-V'!$F$9/15 -> 29.556534 | U42: =IF(T42<0,T42+24,IF(T42>24,T42-24,T42)) -> 5.5565336 | V42: =U42-B42 -> -1.6410664 | W42: =V42*15 -> -24.615995 | X42: =IF(W42<0,W42+360,W42) -> 335.384 | Y42: =-SIN(RADIANS(X42)) -> 0.41653461 | Z42: =TAN(RADIANS(C42))*COS(RADIANS('Data Entry-V'!$F$8))-SIN(RADIANS('Data Entry-V'!$F$8))*COS(RADIANS(X42)) -> 0.62425742 | AA42: =DEGREES(ATAN2(Z42,Y42)) -> 33.713127 | AB42: =IF(AA42<0,AA42+360,AA42) -> 33.713127 | AC42: =DEGREES(ASIN((SIN(RADIANS('Data Entry-V'!$F$8))*SIN(RADIANS(C42)))+(COS(RADIANS('Data Entry-V'!$F$8))*COS(RADIANS(C42))*COS(RADIANS((U42-B42)*15))))) -> 41.684895 | AD42: =1/(COS((4*ATAN(1))/2-(AC42*(4*ATAN(1))/180))) -> 1.5036837 | AE42: =IF(AC42>10,AD42-((AD42-1)*(0.0018161+(AD42-1)*(0.002875+(AD42-1)*0.0008083))),"") -> 1.5019363
A43: HD 50931 | B43: 6.9263 | C43: 8.3243 | D43: 6.28 | E43: 0.04 | F43: 0.06 | G43: =IF($AH$3>0.5,($AH$2+2415019)+((((HOUR($AH$3)*60)+MINUTE($AH$3))/1440+DAY($AH$2))-0.5)-DAY($AH$2),($AH$2+2415019)+((((HOUR($AH$3)*60)+MINUTE($AH$3))/1440+DAY($AH$2))-1.5)-DAY($AH$2)+1) -> 2461051.9 | H43: =IF((G43-ROUNDDOWN(G43,0))<0.5,ROUNDDOWN(G43,0)-0.5,ROUNDDOWN(G43,0)+0.5) -> 2461051.5 | I43: =$AH$3*24 -> 10.5 | J43: =G43-2451545 -> 9506.9375 | K43: =G43-2451545 -> 9506.9375 | L43: =AVERAGE(H43-2451545)/36525 -> 0.26027379 | M43: =6.697374558+(0.065707485828*K43)+(1.0027379093*I43)+(0.0854103*L43)+(0.000025862*L43*L43) -> 641.92532 | N43: =M43-24*(ROUNDDOWN(M43/24,0)) -> 17.925315 | O43: =125.04-0.052954*J43 -> -378.39037 | P43: =280.47+0.98565*J43 -> 9650.9829 | Q43: =23.4393-0.0000004*J43 -> 23.435497 | R43: =-0.000319*SIN(RADIANS(O43))-0.000024*SIN((RADIANS(2*P43))) -> 0.00011668967 | S43: =N43+R43*COS(RADIANS(Q43)) -> 17.925423 | T43: =S43-'Data Entry-V'!$F$9/15 -> 29.556534 | U43: =IF(T43<0,T43+24,IF(T43>24,T43-24,T43)) -> 5.5565336 | V43: =U43-B43 -> -1.3697664 | W43: =V43*15 -> -20.546495 | X43: =IF(W43<0,W43+360,W43) -> 339.4535 | Y43: =-SIN(RADIANS(X43)) -> 0.35096737 | Z43: =TAN(RADIANS(C43))*COS(RADIANS('Data Entry-V'!$F$8))-SIN(RADIANS('Data Entry-V'!$F$8))*COS(RADIANS(X43)) -> 0.67846435 | AA43: =DEGREES(ATAN2(Z43,Y43)) -> 27.352376 | AB43: =IF(AA43<0,AA43+360,AA43) -> 27.352376 | AC43: =DEGREES(ASIN((SIN(RADIANS('Data Entry-V'!$F$8))*SIN(RADIANS(C43)))+(COS(RADIANS('Data Entry-V'!$F$8))*COS(RADIANS(C43))*COS(RADIANS((U43-B43)*15))))) -> 40.90304 | AD43: =1/(COS((4*ATAN(1))/2-(AC43*(4*ATAN(1))/180))) -> 1.5272284 | AE43: =IF(AC43>10,AD43-((AD43-1)*(0.0018161+(AD43-1)*(0.002875+(AD43-1)*0.0008083))),"") -> 1.5253533
A44: HD 18543 | B44: 2.9784 | C44: -2.7828 | D44: 5.23 | E44: 0 | F44: 0.04 | G44: =IF($AH$3>0.5,($AH$2+2415019)+((((HOUR($AH$3)*60)+MINUTE($AH$3))/1440+DAY($AH$2))-0.5)-DAY($AH$2),($AH$2+2415019)+((((HOUR($AH$3)*60)+MINUTE($AH$3))/1440+DAY($AH$2))-1.5)-DAY($AH$2)+1) -> 2461051.9 | H44: =IF((G44-ROUNDDOWN(G44,0))<0.5,ROUNDDOWN(G44,0)-0.5,ROUNDDOWN(G44,0)+0.5) -> 2461051.5 | I44: =$AH$3*24 -> 10.5 | J44: =G44-2451545 -> 9506.9375 | K44: =G44-2451545 -> 9506.9375 | L44: =AVERAGE(H44-2451545)/36525 -> 0.26027379 | M44: =6.697374558+(0.065707485828*K44)+(1.0027379093*I44)+(0.0854103*L44)+(0.000025862*L44*L44) -> 641.92532 | N44: =M44-24*(ROUNDDOWN(M44/24,0)) -> 17.925315 | O44: =125.04-0.052954*J44 -> -378.39037 | P44: =280.47+0.98565*J44 -> 9650.9829 | Q44: =23.4393-0.0000004*J44 -> 23.435497 | R44: =-0.000319*SIN(RADIANS(O44))-0.000024*SIN((RADIANS(2*P44))) -> 0.00011668967 | S44: =N44+R44*COS(RADIANS(Q44)) -> 17.925423 | T44: =S44-'Data Entry-V'!$F$9/15 -> 29.556534 | U44: =IF(T44<0,T44+24,IF(T44>24,T44-24,T44)) -> 5.5565336 | V44: =U44-B44 -> 2.5781336 | W44: =V44*15 -> 38.672005 | X44: =IF(W44<0,W44+360,W44) -> 38.672005 | Y44: =-SIN(RADIANS(X44)) -> -0.62486125 | Z44: =TAN(RADIANS(C44))*COS(RADIANS('Data Entry-V'!$F$8))-SIN(RADIANS('Data Entry-V'!$F$8))*COS(RADIANS(X44)) -> 0.4291384 | AA44: =DEGREES(ATAN2(Z44,Y44)) -> -55.519737 | AB44: =IF(AA44<0,AA44+360,AA44) -> 304.48026 | AC44: =DEGREES(ASIN((SIN(RADIANS('Data Entry-V'!$F$8))*SIN(RADIANS(C44)))+(COS(RADIANS('Data Entry-V'!$F$8))*COS(RADIANS(C44))*COS(RADIANS((U44-B44)*15))))) -> 40.787523 | AD44: =1/(COS((4*ATAN(1))/2-(AC44*(4*ATAN(1))/180))) -> 1.5307941 | AE44: =IF(AC44>10,AD44-((AD44-1)*(0.0018161+(AD44-1)*(0.002875+(AD44-1)*0.0008083))),"") -> 1.5288992
A45: eta Phe | B45: 0.8892 | C45: -57.4631 | D45: 4.36 | E45: 0 | F45: -0.03 | G45: =IF($AH$3>0.5,($AH$2+2415019)+((((HOUR($AH$3)*60)+MINUTE($AH$3))/1440+DAY($AH$2))-0.5)-DAY($AH$2),($AH$2+2415019)+((((HOUR($AH$3)*60)+MINUTE($AH$3))/1440+DAY($AH$2))-1.5)-DAY($AH$2)+1) -> 2461051.9 | H45: =IF((G45-ROUNDDOWN(G45,0))<0.5,ROUNDDOWN(G45,0)-0.5,ROUNDDOWN(G45,0)+0.5) -> 2461051.5 | I45: =$AH$3*24 -> 10.5 | J45: =G45-2451545 -> 9506.9375 | K45: =G45-2451545 -> 9506.9375 | L45: =AVERAGE(H45-2451545)/36525 -> 0.26027379 | M45: =6.697374558+(0.065707485828*K45)+(1.0027379093*I45)+(0.0854103*L45)+(0.000025862*L45*L45) -> 641.92532 | N45: =M45-24*(ROUNDDOWN(M45/24,0)) -> 17.925315 | O45: =125.04-0.052954*J45 -> -378.39037 | P45: =280.47+0.98565*J45 -> 9650.9829 | Q45: =23.4393-0.0000004*J45 -> 23.435497 | R45: =-0.000319*SIN(RADIANS(O45))-0.000024*SIN((RADIANS(2*P45))) -> 0.00011668967 | S45: =N45+R45*COS(RADIANS(Q45)) -> 17.925423 | T45: =S45-'Data Entry-V'!$F$9/15 -> 29.556534 | U45: =IF(T45<0,T45+24,IF(T45>24,T45-24,T45)) -> 5.5565336 | V45: =U45-B45 -> 4.6673336 | W45: =V45*15 -> 70.010005 | X45: =IF(W45<0,W45+360,W45) -> 70.010005 | Y45: =-SIN(RADIANS(X45)) -> -0.93975233 | Z45: =TAN(RADIANS(C45))*COS(RADIANS('Data Entry-V'!$F$8))-SIN(RADIANS('Data Entry-V'!$F$8))*COS(RADIANS(X45)) -> -1.0496264 | AA45: =DEGREES(ATAN2(Z45,Y45)) -> -138.16126 | AB45: =IF(AA45<0,AA45+360,AA45) -> 221.83874 | AC45: =DEGREES(ASIN((SIN(RADIANS('Data Entry-V'!$F$8))*SIN(RADIANS(C45)))+(COS(RADIANS('Data Entry-V'!$F$8))*COS(RADIANS(C45))*COS(RADIANS((U45-B45)*15))))) -> 40.734805 | AD45: =1/(COS((4*ATAN(1))/2-(AC45*(4*ATAN(1))/180))) -> 1.5324289 | AE45: =IF(AC45>10,AD45-((AD45-1)*(0.0018161+(AD45-1)*(0.002875+(AD45-1)*0.0008083))),"") -> 1.5305249
A46: HD 18331 | B46: 2.9437 | C46: -2.3123 | D46: 5.16 | E46: 0.08 | F46: 0.06 | G46: =IF($AH$3>0.5,($AH$2+2415019)+((((HOUR($AH$3)*60)+MINUTE($AH$3))/1440+DAY($AH$2))-0.5)-DAY($AH$2),($AH$2+2415019)+((((HOUR($AH$3)*60)+MINUTE($AH$3))/1440+DAY($AH$2))-1.5)-DAY($AH$2)+1) -> 2461051.9 | H46: =IF((G46-ROUNDDOWN(G46,0))<0.5,ROUNDDOWN(G46,0)-0.5,ROUNDDOWN(G46,0)+0.5) -> 2461051.5 | I46: =$AH$3*24 -> 10.5 | J46: =G46-2451545 -> 9506.9375 | K46: =G46-2451545 -> 9506.9375 | L46: =AVERAGE(H46-2451545)/36525 -> 0.26027379 | M46: =6.697374558+(0.065707485828*K46)+(1.0027379093*I46)+(0.0854103*L46)+(0.000025862*L46*L46) -> 641.92532 | N46: =M46-24*(ROUNDDOWN(M46/24,0)) -> 17.925315 | O46: =125.04-0.052954*J46 -> -378.39037 | P46: =280.47+0.98565*J46 -> 9650.9829 | Q46: =23.4393-0.0000004*J46 -> 23.435497 | R46: =-0.000319*SIN(RADIANS(O46))-0.000024*SIN((RADIANS(2*P46))) -> 0.00011668967 | S46: =N46+R46*COS(RADIANS(Q46)) -> 17.925423 | T46: =S46-'Data Entry-V'!$F$9/15 -> 29.556534 | U46: =IF(T46<0,T46+24,IF(T46>24,T46-24,T46)) -> 5.5565336 | V46: =U46-B46 -> 2.6128336 | W46: =V46*15 -> 39.192505 | X46: =IF(W46<0,W46+360,W46) -> 39.192505 | Y46: =-SIN(RADIANS(X46)) -> -0.63192792 | Z46: =TAN(RADIANS(C46))*COS(RADIANS('Data Entry-V'!$F$8))-SIN(RADIANS('Data Entry-V'!$F$8))*COS(RADIANS(X46)) -> 0.43230173 | AA46: =DEGREES(ATAN2(Z46,Y46)) -> -55.623979 | AB46: =IF(AA46<0,AA46+360,AA46) -> 304.37602 | AC46: =DEGREES(ASIN((SIN(RADIANS('Data Entry-V'!$F$8))*SIN(RADIANS(C46)))+(COS(RADIANS('Data Entry-V'!$F$8))*COS(RADIANS(C46))*COS(RADIANS((U46-B46)*15))))) -> 40.090774 | AD46: =1/(COS((4*ATAN(1))/2-(AC46*(4*ATAN(1))/180))) -> 1.552794 | AE46: =IF(AC46>10,AD46-((AD46-1)*(0.0018161+(AD46-1)*(0.002875+(AD46-1)*0.0008083))),"") -> 1.5507749
A47: HD 91375 | B47: 10.5056 | C47: -71.9928 | D47: 4.73 | E47: 0.03 | F47: 0.07 | G47: =IF($AH$3>0.5,($AH$2+2415019)+((((HOUR($AH$3)*60)+MINUTE($AH$3))/1440+DAY($AH$2))-0.5)-DAY($AH$2),($AH$2+2415019)+((((HOUR($AH$3)*60)+MINUTE($AH$3))/1440+DAY($AH$2))-1.5)-DAY($AH$2)+1) -> 2461051.9 | H47: =IF((G47-ROUNDDOWN(G47,0))<0.5,ROUNDDOWN(G47,0)-0.5,ROUNDDOWN(G47,0)+0.5) -> 2461051.5 | I47: =$AH$3*24 -> 10.5 | J47: =G47-2451545 -> 9506.9375 | K47: =G47-2451545 -> 9506.9375 | L47: =AVERAGE(H47-2451545)/36525 -> 0.26027379 | M47: =6.697374558+(0.065707485828*K47)+(1.0027379093*I47)+(0.0854103*L47)+(0.000025862*L47*L47) -> 641.92532 | N47: =M47-24*(ROUNDDOWN(M47/24,0)) -> 17.925315 | O47: =125.04-0.052954*J47 -> -378.39037 | P47: =280.47+0.98565*J47 -> 9650.9829 | Q47: =23.4393-0.0000004*J47 -> 23.435497 | R47: =-0.000319*SIN(RADIANS(O47))-0.000024*SIN((RADIANS(2*P47))) -> 0.00011668967 | S47: =N47+R47*COS(RADIANS(Q47)) -> 17.925423 | T47: =S47-'Data Entry-V'!$F$9/15 -> 29.556534 | U47: =IF(T47<0,T47+24,IF(T47>24,T47-24,T47)) -> 5.5565336 | V47: =U47-B47 -> -4.9490664 | W47: =V47*15 -> -74.235995 | X47: =IF(W47<0,W47+360,W47) -> 285.764 | Y47: =-SIN(RADIANS(X47)) -> 0.96238886 | Z47: =TAN(RADIANS(C47))*COS(RADIANS('Data Entry-V'!$F$8))-SIN(RADIANS('Data Entry-V'!$F$8))*COS(RADIANS(X47)) -> -2.2994052 | AA47: =DEGREES(ATAN2(Z47,Y47)) -> 157.28883 | AB47: =IF(AA47<0,AA47+360,AA47) -> 157.28883 | AC47: =DEGREES(ASIN((SIN(RADIANS('Data Entry-V'!$F$8))*SIN(RADIANS(C47)))+(COS(RADIANS('Data Entry-V'!$F$8))*COS(RADIANS(C47))*COS(RADIANS((U47-B47)*15))))) -> 39.594127 | AD47: =1/(COS((4*ATAN(1))/2-(AC47*(4*ATAN(1))/180))) -> 1.5690089 | AE47: =IF(AC47>10,AD47-((AD47-1)*(0.0018161+(AD47-1)*(0.002875+(AD47-1)*0.0008083))),"") -> 1.5668958
A48: HD 73997 | B48: 8.6838 | C48: -9.052 | D48: 6.62 | E48: -0.02 | F48: 0.02 | G48: =IF($AH$3>0.5,($AH$2+2415019)+((((HOUR($AH$3)*60)+MINUTE($AH$3))/1440+DAY($AH$2))-0.5)-DAY($AH$2),($AH$2+2415019)+((((HOUR($AH$3)*60)+MINUTE($AH$3))/1440+DAY($AH$2))-1.5)-DAY($AH$2)+1) -> 2461051.9 | H48: =IF((G48-ROUNDDOWN(G48,0))<0.5,ROUNDDOWN(G48,0)-0.5,ROUNDDOWN(G48,0)+0.5) -> 2461051.5 | I48: =$AH$3*24 -> 10.5 | J48: =G48-2451545 -> 9506.9375 | K48: =G48-2451545 -> 9506.9375 | L48: =AVERAGE(H48-2451545)/36525 -> 0.26027379 | M48: =6.697374558+(0.065707485828*K48)+(1.0027379093*I48)+(0.0854103*L48)+(0.000025862*L48*L48) -> 641.92532 | N48: =M48-24*(ROUNDDOWN(M48/24,0)) -> 17.925315 | O48: =125.04-0.052954*J48 -> -378.39037 | P48: =280.47+0.98565*J48 -> 9650.9829 | Q48: =23.4393-0.0000004*J48 -> 23.435497 | R48: =-0.000319*SIN(RADIANS(O48))-0.000024*SIN((RADIANS(2*P48))) -> 0.00011668967 | S48: =N48+R48*COS(RADIANS(Q48)) -> 17.925423 | T48: =S48-'Data Entry-V'!$F$9/15 -> 29.556534 | U48: =IF(T48<0,T48+24,IF(T48>24,T48-24,T48)) -> 5.5565336 | V48: =U48-B48 -> -3.1272664 | W48: =V48*15 -> -46.908995 | X48: =IF(W48<0,W48+360,W48) -> 313.091 | Y48: =-SIN(RADIANS(X48)) -> 0.73026954 | Z48: =TAN(RADIANS(C48))*COS(RADIANS('Data Entry-V'!$F$8))-SIN(RADIANS('Data Entry-V'!$F$8))*COS(RADIANS(X48)) -> 0.28203371 | AA48: =DEGREES(ATAN2(Z48,Y48)) -> 68.883192 | AB48: =IF(AA48<0,AA48+360,AA48) -> 68.883192 | AC48: =DEGREES(ASIN((SIN(RADIANS('Data Entry-V'!$F$8))*SIN(RADIANS(C48)))+(COS(RADIANS('Data Entry-V'!$F$8))*COS(RADIANS(C48))*COS(RADIANS((U48-B48)*15))))) -> 39.367877 | AD48: =1/(COS((4*ATAN(1))/2-(AC48*(4*ATAN(1))/180))) -> 1.5765481 | AE48: =IF(AC48>10,AD48-((AD48-1)*(0.0018161+(AD48-1)*(0.002875+(AD48-1)*0.0008083))),"") -> 1.5743904
A49: HD 13936 | B49: 2.2579 | C49: -9.4665 | D49: 6.54 | E49: -0.01 | F49: -0.07 | G49: =IF($AH$3>0.5,($AH$2+2415019)+((((HOUR($AH$3)*60)+MINUTE($AH$3))/1440+DAY($AH$2))-0.5)-DAY($AH$2),($AH$2+2415019)+((((HOUR($AH$3)*60)+MINUTE($AH$3))/1440+DAY($AH$2))-1.5)-DAY($AH$2)+1) -> 2461051.9 | H49: =IF((G49-ROUNDDOWN(G49,0))<0.5,ROUNDDOWN(G49,0)-0.5,ROUNDDOWN(G49,0)+0.5) -> 2461051.5 | I49: =$AH$3*24 -> 10.5 | J49: =G49-2451545 -> 9506.9375 | K49: =G49-2451545 -> 9506.9375 | L49: =AVERAGE(H49-2451545)/36525 -> 0.26027379 | M49: =6.697374558+(0.065707485828*K49)+(1.0027379093*I49)+(0.0854103*L49)+(0.000025862*L49*L49) -> 641.92532 | N49: =M49-24*(ROUNDDOWN(M49/24,0)) -> 17.925315 | O49: =125.04-0.052954*J49 -> -378.39037 | P49: =280.47+0.98565*J49 -> 9650.9829 | Q49: =23.4393-0.0000004*J49 -> 23.435497 | R49: =-0.000319*SIN(RADIANS(O49))-0.000024*SIN((RADIANS(2*P49))) -> 0.00011668967 | S49: =N49+R49*COS(RADIANS(Q49)) -> 17.925423 | T49: =S49-'Data Entry-V'!$F$9/15 -> 29.556534 | U49: =IF(T49<0,T49+24,IF(T49>24,T49-24,T49)) -> 5.5565336 | V49: =U49-B49 -> 3.2986336 | W49: =V49*15 -> 49.479505 | X49: =IF(W49<0,W49+360,W49) -> 49.479505 | Y49: =-SIN(RADIANS(X49)) -> -0.7601736 | Z49: =TAN(RADIANS(C49))*COS(RADIANS('Data Entry-V'!$F$8))-SIN(RADIANS('Data Entry-V'!$F$8))*COS(RADIANS(X49)) -> 0.25604312 | AA49: =DEGREES(ATAN2(Z49,Y49)) -> -71.385348 | AB49: =IF(AA49<0,AA49+360,AA49) -> 288.61465 | AC49: =DEGREES(ASIN((SIN(RADIANS('Data Entry-V'!$F$8))*SIN(RADIANS(C49)))+(COS(RADIANS('Data Entry-V'!$F$8))*COS(RADIANS(C49))*COS(RADIANS((U49-B49)*15))))) -> 37.701048 | AD49: =1/(COS((4*ATAN(1))/2-(AC49*(4*ATAN(1))/180))) -> 1.635212 | AE49: =IF(AC49>10,AD49-((AD49-1)*(0.0018161+(AD49-1)*(0.002875+(AD49-1)*0.0008083))),"") -> 1.6326911
A50: HD 72660 | B50: 8.5671 | C50: -2.1516 | D50: 5.8 | E50: 0 | F50: 0 | G50: =IF($AH$3>0.5,($AH$2+2415019)+((((HOUR($AH$3)*60)+MINUTE($AH$3))/1440+DAY($AH$2))-0.5)-DAY($AH$2),($AH$2+2415019)+((((HOUR($AH$3)*60)+MINUTE($AH$3))/1440+DAY($AH$2))-1.5)-DAY($AH$2)+1) -> 2461051.9 | H50: =IF((G50-ROUNDDOWN(G50,0))<0.5,ROUNDDOWN(G50,0)-0.5,ROUNDDOWN(G50,0)+0.5) -> 2461051.5 | I50: =$AH$3*24 -> 10.5 | J50: =G50-2451545 -> 9506.9375 | K50: =G50-2451545 -> 9506.9375 | L50: =AVERAGE(H50-2451545)/36525 -> 0.26027379 | M50: =6.697374558+(0.065707485828*K50)+(1.0027379093*I50)+(0.0854103*L50)+(0.000025862*L50*L50) -> 641.92532 | N50: =M50-24*(ROUNDDOWN(M50/24,0)) -> 17.925315 | O50: =125.04-0.052954*J50 -> -378.39037 | P50: =280.47+0.98565*J50 -> 9650.9829 | Q50: =23.4393-0.0000004*J50 -> 23.435497 | R50: =-0.000319*SIN(RADIANS(O50))-0.000024*SIN((RADIANS(2*P50))) -> 0.00011668967 | S50: =N50+R50*COS(RADIANS(Q50)) -> 17.925423 | T50: =S50-'Data Entry-V'!$F$9/15 -> 29.556534 | U50: =IF(T50<0,T50+24,IF(T50>24,T50-24,T50)) -> 5.5565336 | V50: =U50-B50 -> -3.0105664 | W50: =V50*15 -> -45.158495 | X50: =IF(W50<0,W50+360,W50) -> 314.8415 | Y50: =-SIN(RADIANS(X50)) -> 0.70906012 | Z50: =TAN(RADIANS(C50))*COS(RADIANS('Data Entry-V'!$F$8))-SIN(RADIANS('Data Entry-V'!$F$8))*COS(RADIANS(X50)) -> 0.39265822 | AA50: =DEGREES(ATAN2(Z50,Y50)) -> 61.023508 | AB50: =IF(AA50<0,AA50+360,AA50) -> 61.023508 | AC50: =DEGREES(ASIN((SIN(RADIANS('Data Entry-V'!$F$8))*SIN(RADIANS(C50)))+(COS(RADIANS('Data Entry-V'!$F$8))*COS(RADIANS(C50))*COS(RADIANS((U50-B50)*15))))) -> 35.908848 | AD50: =1/(COS((4*ATAN(1))/2-(AC50*(4*ATAN(1))/180))) -> 1.7050373 | AE50: =IF(AC50>10,AD50-((AD50-1)*(0.0018161+(AD50-1)*(0.002875+(AD50-1)*0.0008083))),"") -> 1.7020445
A51: HD 65900 | B51: 8.0205 | C51: 4.8667 | D51: 5.64 | E51: 0.08 | F51: 0.01 | G51: =IF($AH$3>0.5,($AH$2+2415019)+((((HOUR($AH$3)*60)+MINUTE($AH$3))/1440+DAY($AH$2))-0.5)-DAY($AH$2),($AH$2+2415019)+((((HOUR($AH$3)*60)+MINUTE($AH$3))/1440+DAY($AH$2))-1.5)-DAY($AH$2)+1) -> 2461051.9 | H51: =IF((G51-ROUNDDOWN(G51,0))<0.5,ROUNDDOWN(G51,0)-0.5,ROUNDDOWN(G51,0)+0.5) -> 2461051.5 | I51: =$AH$3*24 -> 10.5 | J51: =G51-2451545 -> 9506.9375 | K51: =G51-2451545 -> 9506.9375 | L51: =AVERAGE(H51-2451545)/36525 -> 0.26027379 | M51: =6.697374558+(0.065707485828*K51)+(1.0027379093*I51)+(0.0854103*L51)+(0.000025862*L51*L51) -> 641.92532 | N51: =M51-24*(ROUNDDOWN(M51/24,0)) -> 17.925315 | O51: =125.04-0.052954*J51 -> -378.39037 | P51: =280.47+0.98565*J51 -> 9650.9829 | Q51: =23.4393-0.0000004*J51 -> 23.435497 | R51: =-0.000319*SIN(RADIANS(O51))-0.000024*SIN((RADIANS(2*P51))) -> 0.00011668967 | S51: =N51+R51*COS(RADIANS(Q51)) -> 17.925423 | T51: =S51-'Data Entry-V'!$F$9/15 -> 29.556534 | U51: =IF(T51<0,T51+24,IF(T51>24,T51-24,T51)) -> 5.5565336 | V51: =U51-B51 -> -2.4639664 | W51: =V51*15 -> -36.959495 | X51: =IF(W51<0,W51+360,W51) -> 323.0405 | Y51: =-SIN(RADIANS(X51)) -> 0.60125029 | Z51: =TAN(RADIANS(C51))*COS(RADIANS('Data Entry-V'!$F$8))-SIN(RADIANS('Data Entry-V'!$F$8))*COS(RADIANS(X51)) -> 0.54717684 | AA51: =DEGREES(ATAN2(Z51,Y51)) -> 47.695769 | AB51: =IF(AA51<0,AA51+360,AA51) -> 47.695769 | AC51: =DEGREES(ASIN((SIN(RADIANS('Data Entry-V'!$F$8))*SIN(RADIANS(C51)))+(COS(RADIANS('Data Entry-V'!$F$8))*COS(RADIANS(C51))*COS(RADIANS((U51-B51)*15))))) -> 35.9012 | AD51: =1/(COS((4*ATAN(1))/2-(AC51*(4*ATAN(1))/180))) -> 1.7053517 | AE51: =IF(AC51>10,AD51-((AD51-1)*(0.0018161+(AD51-1)*(0.002875+(AD51-1)*0.0008083))),"") -> 1.7023567
A52: lam1 Phe | B52: 0.5236 | C52: -48.8035 | D52: 4.77 | E52: 0.01 | F52: 0.04 | G52: =IF($AH$3>0.5,($AH$2+2415019)+((((HOUR($AH$3)*60)+MINUTE($AH$3))/1440+DAY($AH$2))-0.5)-DAY($AH$2),($AH$2+2415019)+((((HOUR($AH$3)*60)+MINUTE($AH$3))/1440+DAY($AH$2))-1.5)-DAY($AH$2)+1) -> 2461051.9 | H52: =IF((G52-ROUNDDOWN(G52,0))<0.5,ROUNDDOWN(G52,0)-0.5,ROUNDDOWN(G52,0)+0.5) -> 2461051.5 | I52: =$AH$3*24 -> 10.5 | J52: =G52-2451545 -> 9506.9375 | K52: =G52-2451545 -> 9506.9375 | L52: =AVERAGE(H52-2451545)/36525 -> 0.26027379 | M52: =6.697374558+(0.065707485828*K52)+(1.0027379093*I52)+(0.0854103*L52)+(0.000025862*L52*L52) -> 641.92532 | N52: =M52-24*(ROUNDDOWN(M52/24,0)) -> 17.925315 | O52: =125.04-0.052954*J52 -> -378.39037 | P52: =280.47+0.98565*J52 -> 9650.9829 | Q52: =23.4393-0.0000004*J52 -> 23.435497 | R52: =-0.000319*SIN(RADIANS(O52))-0.000024*SIN((RADIANS(2*P52))) -> 0.00011668967 | S52: =N52+R52*COS(RADIANS(Q52)) -> 17.925423 | T52: =S52-'Data Entry-V'!$F$9/15 -> 29.556534 | U52: =IF(T52<0,T52+24,IF(T52>24,T52-24,T52)) -> 5.5565336 | V52: =U52-B52 -> 5.0329336 | W52: =V52*15 -> 75.494005 | X52: =IF(W52<0,W52+360,W52) -> 75.494005 | Y52: =-SIN(RADIANS(X52)) -> -0.96812144 | Z52: =TAN(RADIANS(C52))*COS(RADIANS('Data Entry-V'!$F$8))-SIN(RADIANS('Data Entry-V'!$F$8))*COS(RADIANS(X52)) -> -0.76422166 | AA52: =DEGREES(ATAN2(Z52,Y52)) -> -128.28707 | AB52: =IF(AA52<0,AA52+360,AA52) -> 231.71293 | AC52: =DEGREES(ASIN((SIN(RADIANS('Data Entry-V'!$F$8))*SIN(RADIANS(C52)))+(COS(RADIANS('Data Entry-V'!$F$8))*COS(RADIANS(C52))*COS(RADIANS((U52-B52)*15))))) -> 35.671295 | AD52: =1/(COS((4*ATAN(1))/2-(AC52*(4*ATAN(1))/180))) -> 1.7148709 | AE52: =IF(AC52>10,AD52-((AD52-1)*(0.0018161+(AD52-1)*(0.002875+(AD52-1)*0.0008083))),"") -> 1.711808
